<?xml version="1.0" ?>
<!-- =================================================================================== -->
<!-- |    This document was autogenerated by xacro from clownbot.xacro                 | -->
<!-- |    EDITING THIS FILE BY HAND IS NOT RECOMMENDED                                 | -->
<!-- =================================================================================== -->
<robot name="clownbot">
  <link name="base_footprint"/>
  <joint name="base_footprint_to_base_link" type="fixed">
    <parent link="base_footprint"/>
    <child link="base_link"/>
    <origin rpy="0 0 0" xyz="0 0 0.04"/>
  </joint>
  <link name="base_link">
    <visual>
      <origin rpy="0 0 0" xyz="0 0 0"/>
      <geometry>
        <mesh filename="package://clownbot_description/meshes/base.dae"/>
      </geometry>
    </visual>
    <collision>
      <origin rpy="0 0 0" xyz="0 0 0"/>
      <geometry>
        <cylinder length="0.06" radius="0.15"/>
      </geometry>
    </collision>
    <inertial>
      <mass value="5"/>
      <inertia ixx="0.029625" ixy="0.0" ixz="0.0" iyy="0.029625" iyz="0.0" izz="0.056249999999999994"/>
    </inertial>
  </link>
  <joint name="base_link_to_right_wheel" type="continuous">
    <parent link="base_link"/>
    <child link="right_wheel"/>
    <origin rpy="0 0 0" xyz="0 -0.15 0"/>
    <axis xyz="0 1 0"/>
  </joint>
  <link name="right_wheel">
    <visual>
      <origin rpy="0 0 1.5707963267948966" xyz="0 0 0"/>
      <geometry>
        <mesh filename="package://clownbot_description/meshes/wheel.dae"/>
      </geometry>
    </visual>
    <collision>
      <origin rpy="1.5707963267948966 0 0" xyz="0 0 0"/>
      <geometry>
        <cylinder length="0.01" radius="0.04"/>
      </geometry>
    </collision>
    <inertial>
      <mass value="0.1"/>
      <inertia ixx="4.0833333333333334e-05" ixy="0.0" ixz="0.0" iyy="4.0833333333333334e-05" iyz="0.0" izz="8e-05"/>
    </inertial>
  </link>
  <gazebo reference="right_wheel">
    <mu1>100000.0</mu1>
    <mu2>100000.0</mu2>
    <kp>1000000.0</kp>
    <kd>1.0</kd>
  </gazebo>
  <joint name="base_link_to_left_wheel" type="continuous">
    <parent link="base_link"/>
    <child link="left_wheel"/>
    <origin rpy="0 0 0" xyz="0 0.15 0"/>
    <axis xyz="0 1 0"/>
  </joint>
  <link name="left_wheel">
    <visual>
      <origin rpy="0 0 -1.5707963267948966" xyz="0 0 0"/>
      <geometry>
        <mesh filename="package://clownbot_description/meshes/wheel.dae"/>
      </geometry>
    </visual>
    <collision>
      <origin rpy="1.5707963267948966 0 0" xyz="0 0 0"/>
      <geometry>
        <cylinder length="0.01" radius="0.04"/>
      </geometry>
    </collision>
    <inertial>
      <mass value="0.1"/>
      <inertia ixx="4.0833333333333334e-05" ixy="0.0" ixz="0.0" iyy="4.0833333333333334e-05" iyz="0.0" izz="8e-05"/>
    </inertial>
  </link>
  <gazebo reference="left_wheel">
    <mu1>100000.0</mu1>
    <mu2>100000.0</mu2>
    <kp>1000000.0</kp>
    <kd>1.0</kd>
  </gazebo>
  <joint name="base_link_to_front_caster" type="fixed">
    <parent link="base_link"/>
    <child link="front_caster"/>
    <origin rpy="0 0 0" xyz="0.1 0 -0.03365"/>
  </joint>
  <link name="front_caster">
    <visual>
      <origin rpy="0 3.141592653589793 1.5707963267948966" xyz="0 0 0.00535"/>
      <geometry>
        <mesh filename="package://clownbot_description/meshes/caster.dae"/>
      </geometry>
    </visual>
    <collision>
      <geometry>
        <sphere radius="0.00635"/>
      </geometry>
    </collision>
    <inertial>
      <mass value="0.01"/>
      <inertia ixx="1.6128999999999998e-07" ixy="0.0" ixz="0.0" iyy="1.6128999999999998e-07" iyz="0.0" izz="1.6128999999999998e-07"/>
    </inertial>
  </link>
  <joint name="base_link_to_back_caster" type="fixed">
    <parent link="base_link"/>
    <child link="back_caster"/>
    <origin rpy="0 0 0" xyz="-0.1 0 -0.03365"/>
  </joint>
  <link name="back_caster">
    <visual>
      <origin rpy="0 3.141592653589793 1.5707963267948966" xyz="0 0 0.00535"/>
      <geometry>
        <mesh filename="package://clownbot_description/meshes/caster.dae"/>
      </geometry>
    </visual>
    <collision>
      <geometry>
        <sphere radius="0.00635"/>
      </geometry>
    </collision>
    <inertial>
      <mass value="0.01"/>
      <inertia ixx="1.6128999999999998e-07" ixy="0.0" ixz="0.0" iyy="1.6128999999999998e-07" iyz="0.0" izz="1.6128999999999998e-07"/>
    </inertial>
  </link>
  <gazebo>
    <plugin filename="libgazebo_ros_diff_drive.so" name="differential_drive_controller">
      <updateRate>20</updateRate>
      <leftJoint>base_link_to_left_wheel</leftJoint>
      <rightJoint>base_link_to_right_wheel</rightJoint>
      <wheelSeparation>0.3</wheelSeparation>
      <wheelDiameter>0.08</wheelDiameter>
      <wheelAcceleration>1.0</wheelAcceleration>
      <wheelTorque>20</wheelTorque>
      <commandTopic>/cmd_vel</commandTopic>
      <odometryTopic>/odom</odometryTopic>
      <odometryFrame>odom</odometryFrame>
      <robotBaseFrame>base_footprint</robotBaseFrame>
      <odometrySource>world</odometrySource>
      <publishWheelTF>false</publishWheelTF>
      <publishOdomTF>true</publishOdomTF>
      <publishTf>1</publishTf>
      <publishWheelJointState>false</publishWheelJointState>
      <legacyMode>false</legacyMode>
      <rosDebugLevel>warn</rosDebugLevel>
    </plugin>
  </gazebo>
</robot>

